reports/train_11-1_11-21_test_11-22_11-30.txt
    code_list = [
        # 中证A50十大权重
        '600519sh',  # 贵州茅台
        '300750sz',  # 宁德时代
        '601318sh',  # 中国平安
        '600036sh',  # 招商银行
        '600900sh',  # 长江电力
        '000333sz',  # 美的集团
        '002594sz',  # 比亚迪
        '601899sh',  # 紫金矿业
        '600030sh',  # 中信证券
        '600276sh',  # 恒瑞医药
    ]

    downsample_args = {
        "strategy": "fraction",
        "value": 0.2,
        "random_state": 42
    }

    train_df, test_df = load_data(
        train_data_folder_list=[
            "data_202111/2D_data_11-1_11-7",
            "data_202111/2D_data_11-8_11-14",
            "data_202111/2D_data_11-15_11-21"
        ],
        test_data_folder_list=["data_202111/2D_data_11-22_11-30"],
        code_list=code_list,
        downsample_args=downsample_args
    )

    # === Random Forest ===
    print("\nTraining Random Forest...")
    start = time.time()
    rf = RandomForestClassifier(
        n_estimators=50,
        max_depth=15, 
        n_jobs=-1, 
        verbose=1, 
        random_state=42
    )
    rf.fit(X_train_flat, y_train)
    elapsed = time.time() - start
    print(f"Time taken: {elapsed:.2f}s")
    y_pred_rf = rf.predict(X_test_flat)
    results['rf'] = classification_report(y_test, y_pred_rf, digits=4)
    print("Random Forest:\n", results['rf'])

    # === XGBoost ===
    print("\nTraining XGBoost...")
    start = time.time()
    xgb = XGBClassifier(
        max_depth=6,
        n_estimators=50,
        learning_rate=0.1,
        subsample=0.8,
        colsample_bytree=0.5,
        tree_method='hist',  # 更快
        n_jobs=-1,
        verbosity=1,
        eval_metric='logloss'
    )
    xgb.fit(X_train_flat, y_train)
    elapsed = time.time() - start
    print(f"Time taken: {elapsed:.2f}s")
    y_pred_xgb = xgb.predict(X_test_flat)
    results['xgb'] = classification_report(y_test, y_pred_xgb, digits=4)
    print("XGBoost:\n", results['xgb'])


训练集大小: (113676, 13440), 测试集大小: (36099, 13440)
训练集标签分布: (array([0., 1.]), array([68918, 44758]))
测试集标签分布: (array([0., 1.]), array([22742, 13357]))

22742 / 36099 = 0.6300

训练并评估 Baseline 模型...

Training Random Forest...
[Parallel(n_jobs=-1)]: Using backend ThreadingBackend with 8 concurrent workers.
[Parallel(n_jobs=-1)]: Done  34 tasks      | elapsed:   13.8s
[Parallel(n_jobs=-1)]: Done  50 out of  50 | elapsed:   18.0s finished
Time taken: 25.65s
[Parallel(n_jobs=8)]: Using backend ThreadingBackend with 8 concurrent workers.
[Parallel(n_jobs=8)]: Done  34 tasks      | elapsed:    0.0s
[Parallel(n_jobs=8)]: Done  50 out of  50 | elapsed:    0.1s finished
Random Forest:
               precision    recall  f1-score   support

         0.0     0.6729    0.8748    0.7607     22742
         1.0     0.5641    0.2760    0.3706     13357

    accuracy                         0.6532     36099
   macro avg     0.6185    0.5754    0.5656     36099
weighted avg     0.6326    0.6532    0.6163     36099


Training XGBoost...

Time taken: 221.45s
XGBoost:
               precision    recall  f1-score   support

         0.0     0.7242    0.4774    0.5754     22742
         1.0     0.4369    0.6904    0.5352     13357

    accuracy                         0.5562     36099
   macro avg     0.5806    0.5839    0.5553     36099
weighted avg     0.6179    0.5562    0.5605     36099






    # === Random Forest ===
    print("\nTraining Random Forest...")
    start = time.time()
    rf = RandomForestClassifier(
        n_estimators=200,        # 增加树数量，增强模型稳定性
        max_depth=10,            # 控制单棵树复杂度，防止过拟合
        min_samples_split=10,    # 控制分裂，防止小样本暴力分裂
        min_samples_leaf=5,      # 增强泛化能力
        max_features='sqrt',     # 降低相关性提升泛化
        n_jobs=-1,
        random_state=42,
        verbose=1
    )

    rf.fit(X_train_flat, y_train)
    elapsed = time.time() - start
    print(f"Time taken: {elapsed:.2f}s")
    y_pred_rf = rf.predict(X_test_flat)
    results['rf'] = classification_report(y_test, y_pred_rf, digits=4)
    print("Random Forest:\n", results['rf'])

    # === XGBoost ===
    print("\nTraining XGBoost...")
    start = time.time()
    xgb = XGBClassifier(
        n_estimators=300,         # 提高容量
        learning_rate=0.05,       # 降低每次更新步长，减少过拟合风险
        max_depth=8,              # 增强模型表达力
        subsample=0.8,
        colsample_bytree=0.8,     # 用更多特征
        reg_alpha=1.0,            # L1正则，防止过拟合
        reg_lambda=1.0,           # L2正则
        tree_method='hist',
        n_jobs=-1,
        verbosity=1,
        eval_metric='logloss'
    )

    xgb.fit(X_train_flat, y_train)
    elapsed = time.time() - start
    print(f"Time taken: {elapsed:.2f}s")
    y_pred_xgb = xgb.predict(X_test_flat)
    results['xgb'] = classification_report(y_test, y_pred_xgb, digits=4)
    print("XGBoost:\n", results['xgb'])


训练集大小: (113676, 13440), 测试集大小: (36099, 13440)
训练集标签分布: (array([0., 1.]), array([68918, 44758]))
测试集标签分布: (array([0., 1.]), array([22742, 13357]))

22742 / 36099 = 0.6300

训练并评估 Baseline 模型...

Training Random Forest...
[Parallel(n_jobs=-1)]: Using backend ThreadingBackend with 8 concurrent workers.
[Parallel(n_jobs=-1)]: Done  34 tasks      | elapsed:    7.3s
[Parallel(n_jobs=-1)]: Done 184 tasks      | elapsed:   34.3s
[Parallel(n_jobs=-1)]: Done 200 out of 200 | elapsed:   37.4s finished
Time taken: 45.40s
[Parallel(n_jobs=8)]: Using backend ThreadingBackend with 8 concurrent workers.
[Parallel(n_jobs=8)]: Done  34 tasks      | elapsed:    0.0s
[Parallel(n_jobs=8)]: Done 184 tasks      | elapsed:    0.2s
[Parallel(n_jobs=8)]: Done 200 out of 200 | elapsed:    0.2s finished
Random Forest:
               precision    recall  f1-score   support

         0.0     0.6704    0.8802    0.7611     22742
         1.0     0.5633    0.2632    0.3587     13357

    accuracy                         0.6519     36099
   macro avg     0.6168    0.5717    0.5599     36099
weighted avg     0.6308    0.6519    0.6122     36099


Training XGBoost...
Time taken: 1153.57s
XGBoost:
               precision    recall  f1-score   support

         0.0     0.7085    0.5516    0.6203     22742
         1.0     0.4456    0.6136    0.5163     13357

    accuracy                         0.5746     36099
   macro avg     0.5771    0.5826    0.5683     36099
weighted avg     0.6112    0.5746    0.5818     36099





----------------------------------- CNN ------------------------------------

    downsample_args = {
        "strategy": "fraction",
        "value": 0.5,
        "random_state": 42
    }


### CNNClassifier(): epochs=50, batch_size=128, lr=1e-4

训练集大小: (198937, 1, 224, 60), 测试集大小: (90247, 1, 224, 60)
训练集标签分布: (array([0., 1.]), array([120217,  78720]))
测试集标签分布: (array([0., 1.]), array([56878, 33369]))

56878 / 90247 = 0.6302


开始训练 CNN...
Epoch 1/50: 100%|███████████████████████████████████████████████████████████████████████████████| 1555/1555 [00:13<00:00, 112.51it/s]
Epoch 1: Loss=0.6312 | Val F1=0.6121
Epoch 2/50: 100%|███████████████████████████████████████████████████████████████████████████████| 1555/1555 [00:14<00:00, 107.07it/s]
Epoch 2: Loss=0.6143 | Val F1=0.6222
Epoch 3/50: 100%|███████████████████████████████████████████████████████████████████████████████| 1555/1555 [00:13<00:00, 116.09it/s]
Epoch 3: Loss=0.5978 | Val F1=0.6278
Epoch 4/50: 100%|███████████████████████████████████████████████████████████████████████████████| 1555/1555 [00:13<00:00, 112.48it/s]
Epoch 4: Loss=0.5732 | Val F1=0.6348
Epoch 5/50: 100%|████████████████████████████████████████████████████████████████████████████████| 1555/1555 [00:15<00:00, 99.17it/s]
Epoch 5: Loss=0.5355 | Val F1=0.6373
Epoch 6/50: 100%|████████████████████████████████████████████████████████████████████████████████| 1555/1555 [00:15<00:00, 97.64it/s]
Epoch 6: Loss=0.4850 | Val F1=0.6318
EarlyStopping counter: 1 / 4
Epoch 7/50: 100%|████████████████████████████████████████████████████████████████████████████████| 1555/1555 [00:16<00:00, 96.89it/s]
Epoch 7: Loss=0.4266 | Val F1=0.6364
EarlyStopping counter: 2 / 4
Epoch 8/50: 100%|████████████████████████████████████████████████████████████████████████████████| 1555/1555 [00:16<00:00, 96.52it/s]
